<?xml version="1.0" ?>
<mujoco model="n_link_robot">
	<compiler angle="radian" inertiafromgeom="true"/>
	<asset>
		<texture type="skybox" builtin="gradient" rgb1="0.6 0.6 0.6" rgb2="0.3 0.3 0.3" width="512" height="512"/>
	</asset>
	<visual>
		<map znear="0.001"/>
		<scale forcewidth="0.1"/>
	</visual>
	<default>
		<joint armature="0.0" damping="0.1" frictionloss="0.0" stiffness="0.0" springref="0.0" limited="true"/>
		<geom contype="0" friction="1 0.1 0.1" rgba="1 1 1 1"/>
	</default>
	<option gravity="0 0 -9.81" integrator="implicit" timestep="0.01"/>
	<worldbody>
		<camera name="track" mode="trackcom" pos="0.3 -0.3 0.3" xyaxes="1 0 0 0 1 1" target="body0"/>
		<light cutoff="100" diffuse="1 1 1" dir="-0 0 -1.3" directional="true" exponent="1" pos="0.3 0.3 1.3" specular=".1 .1 .1"/>
		<geom conaffinity="0" contype="0" fromto="0 0 0 0 0 0.02" name="root" rgba="0.8 0.3 0.5 1" size=".011" type="cylinder"/>
		<body name="body0" pos="0 0 0.01">
			<joint axis="0 1 0" name="joint0" pos="0 0 0" type="hinge" damping="0.1" frictionloss="0.0" armature="0.0" stiffness="0.0" springref="0.0" limited="false"/>
			<geom fromto="0 0 0 0 0 0.15" name="link0" rgba="0.0 0.3 0.5 1" size="0.01" type="capsule" density="1000.0"/>
			<body name="fingertip" pos="0 0 0.15">
				<geom contype="0" name="fingertip" pos="0 0 0" rgba="0.0 0.7 0.5 1" size="0.01" type="sphere" density="1000.0"/>
			</body>
		</body>
		<geom conaffinity="0" contype="0" name="target" pos="0.15 0.0 0.15" rgba="0.8 0.1 0.1 1" size=".009" type="sphere"/>
	</worldbody>
	<actuator>
		<motor ctrllimited="true" ctrlrange="-100.0 100.0" gear="1.0" joint="joint0"/>
	</actuator>
</mujoco>
